Workbook
Name \A: #REF!
Name \A: #REF!
Name \A: #REF!
Name \A: #REF!
Name \A: #REF!
Name \A: #REF!
Name \A: #REF!
Name \B: #REF!
Name \B: #REF!
Name \B: #REF!
Name \B: #REF!
Name \B: #REF!
Name \B: #REF!
Name \B: #REF!
Name \C: #REF!
Name \C: #REF!
Name \C: #REF!
Name \C: #REF!
Name \C: #REF!
Name \C: #REF!
Name \C: #REF!
Name \D: #REF!
Name \E: #REF!
Name \F: #REF!
Name \i: #REF!
Name \M: #REF!
Name \N: #REF!
Name \O: #REF!
Name \P: #REF!
Name \Q: #REF!
Name \S: #REF!
Name \T: #REF!
Name \U: #REF!
Name \w: #REF!
Name \X: #REF!
Name \Y: #REF!
Name \Z: #REF!
Name ____7HILLS: #REF!
Name ____Ins2: #REF!
Name ____Ins3: #REF!
Name ____NML9798: #REF!
Name ____NML98: #REF!
Name ____PEG1: #REF!
Name ____RR1: #REF!
Name ____SKY98: #REF!
Name ___1Module2_.PRINT_BCCAM: Insurance_Bonds!___1Module2_.PRINT_BCCAM
Name ___1Module2_.PRINT_BCCAM: Normalize!___1Module2_.PRINT_BCCAM
Name ___1Module2_.PRINT_BCCAM: #N/A
Name ___7HILLS: #REF!
Name ___Ins2: #REF!
Name ___Ins3: #REF!
Name ___MT1: #REF!
Name ___MT2: #REF!
Name ___MT3: #REF!
Name ___NML9798: #REF!
Name ___NML98: #REF!
Name ___PEG1: #REF!
Name ___RR1: #REF!
Name ___SKY98: #REF!
Name __1Module2_.PRINT_BCCAM: #N/A

Sheet Menu Pricing
A2: Lightweight | D2: QT | E2: ='Level 3'!$G$32 -> 261305.65
A3: Product | B3: Concrete Thickness | C3: Sound Mat | D3: Price / SF | E3: Budget | F3: Delta
A4: Basic "$0" | B4: 3/4" | C4: No | D4: 1.4 | E4: =D4*$E$2 -> 365827.91 | F4: =E4-$E$4 -> 0
A5: Basic + (+$1156,783) | B5: 3/4" | C5: 1/8 | D5: 2 | E5: =D5*$E$2 -> 522611.3 | F5: =E5-$E$4 -> 156783.39
A6: Standard (+$313,567) | B6: 1" | C6: 1/4 | D6: 2.6 | E6: =D6*$E$2 -> 679394.69 | F6: =E6-$E$4 -> 313566.78
A9: Unit Cabinets | D9: QT | E9: =SUM(L10:L13,P10:P13,T10:T11) -> 8559 | G9: 390 | I9: UNIT | J9: # UNITS | K9: QTY/UNIT | L9: TOTAL | M9: UNIT | N9: # UNITS | O9: QTY/UNIT | P9: TOTAL | Q9: UNIT | R9: # UNITS | S9: QTY/UNIT | T9: TOTAL
A10: Product | D10: Price / Box | E10: Budget | G10: Cost / Unit | I10: A1A | J10: 9 | K10: =14+2 -> 16 | L10: =J10*K10 -> 144 | M10: A2B | N10: 8 | O10: =10+3+3 -> 16 | P10: =N10*O10 -> 128 | Q10: A3A | R10: 3 | S10: =18+1+3 -> 22 | T10: =R10*S10 -> 66
A11: Thermafoil White "$0" | D11: 137.8 | E11: =D11*E9 -> 1179430.2 | F11: =E11-E11 -> 0 | G11: =E11/G9 -> 3024.18 | I11: B1A | J11: 106 | K11: =20+2 -> 22 | L11: =J11*K11 -> 2332 | M11: B2A | N11: 6 | O11: =20+2 -> 22 | P11: =N11*O11 -> 132 | Q11: B3A | R11: 45 | S11: =20+3+1 -> 24 | T11: =R11*S11 -> 1080
A12: Morning Dew (+$188,298) | D12: 159.8 | E12: =D12*E9 -> 1367728.2 | F12: =E12-E11 -> 188298 | G12: 3507 | I12: B1AE | J12: 3 | K12: =20+2 -> 22 | L12: =J12*K12 -> 66 | M12: B2B | N12: 107 | O12: =21+2+3 -> 26 | P12: =N12*O12 -> 2782
I13: B1B | J13: 60 | K13: =13+1 -> 14 | L13: =J13*K13 -> 840 | M13: B2C | N13: 43 | O13: =21+2 -> 23 | P13: =N13*O13 -> 989
A15: Common Area Cabinets | D15: QT | E15: =SUM(M16:M19) -> 98 | G15: 390 | J15: Level 1 | K15: Level 2 | L15: Level 3 | M15: TOTAL
A16: Product | D16: Price / Box | E16: Budget | G16: Cost / Unit | I16: Bldg 1 | J16: =55+31 -> 86 | K16: =9 -> 9 | L16: =1 -> 1 | M16: =SUM(J16:L16) -> 96
A17: Thermafoil White "$0" | D17: 137.8 | E17: =D17*E15 -> 13504.4 | F17: =E17-E17 -> 0 | G17: =E17/G15 -> 34.626667 | I17: Bldg 2 | J17: 0 | K17: 0 | L17: 0 | M17: =SUM(J17:L17) -> 0
A18: Morning Dew (+$2,156) | D18: 159.8 | E18: =D18*E15 -> 15660.4 | F18: =E18-E17 -> 2156 | G18: =E18/G15 -> 40.154872 | I18: Bldg 3 | J18: =2 -> 2 | K18: 0 | L18: 0 | M18: =SUM(J18:L18) -> 2
A19: Torrey Pines | E19: =85600*1.5 -> 128400 | F19: =E19-E17 -> 114895.6 | G19: =E19/G15 -> 329.23077 | I19: Bldg 4 | J19: 0 | K19: 0 | L19: 0 | M19: =SUM(J19:L19) -> 0
A21: Unit Counter Tops | D21: QT | E21: =SUM(L22:L25,P22:P25,T22:T23) -> 32355.9 | G21: 390 | I21: UNIT | J21: # UNITS | K21: SF/UNIT | L21: TOTAL | M21: UNIT | N21: # UNITS | O21: SF/UNIT | P21: TOTAL | Q21: UNIT | R21: # UNITS | S21: SF/UNIT | T21: TOTAL
A22: Product | C22: Sound Mat | D22: Price / SF | E22: Budget | F22: Delta | G22: Cost / Unit | I22: A1A | J22: 9 | K22: =38.87+23.94 -> 62.81 | L22: =J22*K22 -> 565.29 | M22: A2B | N22: 8 | O22: =39.2+19.93 -> 59.13 | P22: =N22*O22 -> 473.04 | Q22: A3A | R22: 3 | S22: =77.84+24.25 -> 102.09 | T22: =R22*S22 -> 306.27
A23: Arctic White "$0" | B23: 3/4" | C23: No | D23: 24.855498 | E23: =D23*E21 -> 804222.02 | F23: =E23-E23 -> 0 | G23: =E23/G21 -> 2062.1077 | I23: B1A | J23: 106 | K23: =52.72+23.95 -> 76.67 | L23: =J23*K23 -> 8127.02 | M23: B2A | N23: 6 | O23: =64.8+28.49 -> 93.29 | P23: =N23*O23 -> 559.74 | Q23: B3A | R23: 45 | S23: =63.06+20.79 -> 83.85 | T23: =R23*S23 -> 3773.25
A24: Carrera Trigato (+$94,156) | B24: 1" | C24: 1/4 | D24: 28.4 | E24: =D24*E21 -> 918907.56 | F24: =E24-E23 -> 114685.54 | G24: =E24/G21 -> 2356.1732 | I24: B1AE | J24: 3 | K24: =54.22+24.52 -> 78.74 | L24: =J24*K24 -> 236.22 | M24: B2B | N24: 107 | O24: =56.82+28.93 -> 85.75 | P24: =N24*O24 -> 9175.25
I25: B1B | J25: 60 | K25: =64.49+17.65 -> 82.14 | L25: =J25*K25 -> 4928.4 | M25: B2C | N25: 43 | O25: =67.2+30.74 -> 97.94 | P25: =N25*O25 -> 4211.42
A27: Common Area Counter Tops | D27: QT | E27: =SUM(M28:M31) -> 645.31 | G27: 390 | J27: Level 1 | K27: Level 2 | L27: Level 3 | M27: TOTAL
A28: Product | C28: Sound Mat | D28: Price / SF | E28: Budget | F28: Delta | G28: Cost / Unit | I28: Bldg 1 | J28: =510.59+50.75 -> 561.34 | K28: =39.69+7.86 -> 47.55 | L28: =10.04+2.2 -> 12.24 | M28: =SUM(J28:L28) -> 621.13
A29: Arctic White "$0" | B29: 3/4" | C29: No | D29: 24.86 | E29: =D29*E27 -> 16042.407 | F29: =E29-E29 -> 0 | G29: =E29/G27 -> 41.134376 | I29: Bldg 2 | J29: 0 | K29: 0 | L29: 0 | M29: =SUM(J29:L29) -> 0
A30: Carrera Trigato (+$1,878) | B30: 1" | C30: 1/4 | D30: 28.4 | E30: =D30*E27 -> 18326.804 | F30: =E30-E29 -> 2284.3974 | G30: =E30/G27 -> 46.991805 | I30: Bldg 3 | J30: =19.63+4.55 -> 24.18 | K30: 0 | L30: 0 | M30: =SUM(J30:L30) -> 24.18
A31: Torrey Pines | E31: =E19*0.304579439 -> 39108 | F31: =E31-E29 -> 23065.593 | G31: =E31/G27 -> 100.27692 | I31: Bldg 4 | J31: 0 | K31: 0 | L31: 0 | M31: =SUM(J31:L31) -> 0
A33: Unit Flooring | D33: QT | E33: =(SUM(L34:L37,P34:P37,T34:T35))/9 -> 29439.358 | G33: 390 | I33: UNIT | J33: # UNITS | K33: SF/UNIT | L33: TOTAL | M33: UNIT | N33: # UNITS | O33: SF/UNIT | P33: TOTAL | Q33: UNIT | R33: # UNITS | S33: SF/UNIT | T33: TOTAL | V33: ADDITIONAL GROSS SF PER PLANS
A34: Product | B34: Material Thickness | C34: Sound Mat | D34: Price / SY | E34: Budget | F34: Delta | G34: Cost / Unit | I34: A1A | J34: 9 | K34: 551.27 | L34: =J34*K34 -> 4961.43 | M34: A2B | N34: 8 | O34: 738.02 | P34: =N34*O34 -> 5904.16 | Q34: A3A | R34: 3 | S34: 986.11 | T34: =R34*S34 -> 2958.33 | V34: =(676-605)*J34 -> 639 | W34: =(904-806)*N34 -> 784 | X34: =(1216-1097)*R34 -> 357
A35: Sheet Vinyl "$0" | D35: =1.81*9 -> 16.29 | E35: =D35*E33 -> 479567.14 | F35: =E35-E35 -> 0 | G35: =E35/G33 -> 1229.6593 | I35: B1A | J35: 106 | K35: 535.09 | L35: =J35*K35 -> 56719.54 | M35: B2A | N35: 6 | O35: 743.09 | P35: =N35*O35 -> 4458.54 | Q35: B3A | R35: 45 | S35: 1008.6 | T35: =R35*S35 -> 45387 | V35: =(676-605)*J35 -> 7526 | W35: =(901-812)*N35 -> 534 | X35: =(1216-1103)*R35 -> 5085
A36: Vinyl Plank (+$98,033) | D36: =2.18*9 -> 19.62 | E36: =D36*E33 -> 577600.2 | F36: =E36-E35 -> 98033.061 | G36: =E36/G33 -> 1481.0262 | I36: B1AE | J36: 3 | K36: 552.32 | L36: =J36*K36 -> 1656.96 | M36: B2B | N36: 107 | O36: 721.73 | P36: =N36*O36 -> 77225.11 | V36: =(696-624)*J36 -> 216 | W36: =(904-806)*N36 -> 10486
I37: B1B | J37: 60 | K37: 532.53 | L37: =J37*K37 -> 31951.8 | M37: B2C | N37: 43 | O37: 784.45 | P37: =N37*O37 -> 33731.35 | V37: =(686-604)*J37 -> 4920 | W37: =(957-858)*N37 -> 4257
A39: Common Area Flooring | D39: QT | E39: =SUM(M40:M43) -> 67747.26 | G39: 390 | J39: Level 1 | K39: Level 2 | L39: Level 3 | M39: TOTAL
A40: Product | B40: Material Thickness | C40: Sound Mat | D40: Price / SF | E40: Budget | F40: Delta | G40: Cost / Unit | I40: Bldg 1 | J40: =14378.51 -> 14378.51 | K40: =8572.95+873.14 -> 9446.09 | L40: 8550.2 | M40: =SUM(J40:L40) -> 32374.8
A41: Vinyl Plank "$0" | D41: 3.05 | E41: =D41*E39 -> 206629.14 | F41: =E41-E41 -> 0 | G41: =E41/G39 -> 529.81832 | I41: Bldg 2 | J41: =1753.1 -> 1753.1 | K41: 1403.89 | L41: 0 | M41: =SUM(J41:L41) -> 3156.99 | P41: SF | Q41: SY | R41: Takeoff SF/Gross SF on Plans
A42: Tile (+$730,315) | D42: 13.83 | E42: =D42*E39 -> 936944.61 | F42: =E42-E41 -> 730315.46 | G42: =E42/G39 -> 2402.4221 | I42: Bldg 3 | J42: =10377.46 -> 10377.46 | K42: =8755+1050.24 -> 9805.24 | L42: 8719.59 | M42: =SUM(J42:L42) -> 28902.29 | P42: ='Level 3'!B8-(SUM(L22:L25,P22:P25,T22:T23,M28:M31,L34:L37,P34:P37,T34:T35,M40:M43)+1152.99)-(SUM(V34:W37,X34,X35)) -> 20975.32 | Q42: =P42/9 -> 2330.5911 | R42: =SUM(L34:L37,P34:P37,T34:T35)/SUM(L34:L37,P34:P37,T34:T35,V34:W37,X34:X35) -> 0.88389309
I43: Bldg 4 | J43: =1756.85 -> 1756.85 | K43: =1407.15+149.18 -> 1556.33 | L43: 0 | M43: =SUM(J43:L43) -> 3313.18 | P43: =P42/'Level 3'!B8 -> 0.04962987
A44: Offsite Water | D44: QT
A45: Product | C45: Savings | D45: Price / SF
A46: Per Plan | D46: 1772233.6
A47: Value (No Larson Ln Line) | C47: 250000 | D47: =D46-C47 -> 1522233.6
I49: Design | J49: 22140 | O49: 11700
...

Sheet Level 2 - Transmitted
A1: Project Details | D1: Unit Breakdown | H1: Breakdown Per Building | P1: List of Take offs | S1: List of Take offs | V1: List of Take offs
A2: Project | B2: West Henderson | D2: Unit Type | E2: Number | F2: % | H2: Bldg. | I2: Levels | J2: Unit | K2: 1 Br - 1 Ba | L2: 2 Br - 1 Ba | M2: 2 Br - 2 Ba | N2: 3 Br - 2 Ba | O2: GSF | P2: Slab SF | Q2: 145399.85 | R2: GSF (Provided in Matrix) | S2: 1 Br - 1 Ba Counter | T2: 9150.98 | U2: SF | V2: Structural | W2: 59616.52 | AP2: Finish Carpentry | AW2: Exhaust Per Building | BE2: Unit Breakdown | BF2: Wire Shelving LF | BG2: Bedrooms | BH2: Bathrooms | BI2: Unit Count | BJ2: Windows
A3: Budget Level | B3: Level 2 | D3: Studios | E3: 0 | F3: 0 | H3: 1 | I3: 3 | J3: 169 | K3: 87 | L3: 17 | M3: 48 | N3: 17 | O3: 185300 | P3: Elevators | Q3: 4 | R3: Count | S3: 2 Br - 1 Ba Counter | T3: 2673.44 | U3: SF | AA3: Railing Estimate | AE3: Building 3 | AF3: =21*7 -> 147 | AH3: Stucco | AJ3: 1.1 | AP3: Unit Type | AQ3: Number | AR3: TP $ | AS3: % | AT3: % | AW3: Building | AX3: Floors | AY3: U / Floor | AZ3: Total Units | BA3: Cost / U | BB3: Total | BE3: A1A | BF3: 41 | BG3: 1 | BH3: 1 | BI3: 9 | BJ3: 3 | BK3: =BJ3*BI3 -> 27
A4: Product | B4: Affordable | D4: 1 Br - 1 Ba | E4: 178 | F4: 0.45641026 | H4: 2 | I4: 2 | J4: 24 | K4: 9 | L4: 7 | M4: 8 | N4: 0 | O4: 24353 | P4: Elevators Stops | Q4: 12 | R4: Count | S4: 2 Br - 2 Ba Counter | T4: 2893.8 | U4: SF | AA4: Building 1 | AF4: =14*7 -> 98 | AH4: Building 1 | AI4: =88591.52+6310.7+12391.66+5996.96 -> 113290.84 | AJ4: =AI4*$AJ$3 -> 124619.92 | AP4: Studios | AQ4: 0 | AR4: 3192.5 | AS4: 0 | AT4: =AR4*(1+AS4) -> 3192.5 | AW4: Building 1 | AX4: 3 | AY4: 9 | AZ4: =AY4*AX4 -> 27 | BA4: =275 -> 275 | BB4: =BA4*AZ4 -> 7425 | BE4: B1A | BF4: 31 | BG4: 1 | BH4: 1 | BI4: 106 | BJ4: 3 | BK4: =BJ4*BI4 -> 318
A5: UPDATED | B5: 45884 | D5: 2 Br - 1 Ba | E5: 49 | F5: 0.12564103 | H5: 3 | I5: 3 | J5: 173 | K5: 73 | L5: 18 | M5: 51 | N5: 31 | O5: 192543 | P5: Trash Encl. | Q5: 13 | R5: Provided in Site Plan | S5: 3 Br - 2 Ba Counter | T5: 3543.36 | U5: SF | AA5: Northwest | AB5: =21*4+8*8+7*6 -> 190 | AF5: =8*22 -> 176 | AH5: Building 2 | AI5: =31183.77/2 -> 15591.885 | AJ5: =AI5*$AJ$3 -> 17151.074 | AP5: 1 Br - 1 Ba | AQ5: 171 | AR5: 3192.5 | AS5: 0 | AT5: =AR5*(1+AS5) -> 3192.5 | AW5: Building 2 | AX5: 2 | AY5: 2 | AZ5: =AY5*AX5 -> 4 | BA5: =275 -> 275 | BB5: =BA5*AZ5 -> 1100 | BE5: B1AE | BF5: 31 | BG5: 1 | BH5: 1 | BI5: 3 | BJ5: 3 | BK5: =BJ5*BI5 -> 9
A6: Timeline | B6: 26 | D6: 2 Br - 2 Ba | E6: 115 | F6: 0.29487179 | H6: 4 | I6: 2 | J6: 24 | K6: 9 | L6: 7 | M6: 8 | N6: 0 | O6: 24353 | P6: Stairs | Q6: 17 | R6: Count | S6: 1x1 Decks | T6: 3440 | U6: SF | AA6: Southwest | AB6: =14*4+21*2+8*6 -> 146 | AF6: =7*10 -> 70 | AH6: Building 3 | AI6: =65053.99+12730.03+12624.72 -> 90408.74 | AJ6: =AI6*$AJ$3 -> 99449.614 | AP6: 2 Br - 1 Ba | AQ6: 52 | AR6: 3192.5 | AS6: 0 | AT6: =AR6*(1+AS6) -> 3192.5 | AW6: Building 3 | AX6: 2 | AY6: 9 | AZ6: =AY6*AX6 -> 18 | BA6: =275 -> 275 | BB6: =BA6*AZ6 -> 4950 | BE6: B1B | BF6: 19 | BG6: 1 | BH6: 1 | BI6: 60 | BJ6: 2 | BK6: =BJ6*BI6 -> 120
A7: Floors | B7: 2 & 3 Levels | D7: 3 Br - 2 Ba | E7: 48 | F7: 0.12307692 | P7: Pool | Q7: 1 | S7: 2x1 Decks | U7: SF | AA7: Northeast | AB7: =21*2+14*2+8*6 -> 118 | AF7: =SUM(AF3:AF6) -> 491 | AH7: Building 4 | AI7: =31183.77/2 -> 15591.885 | AJ7: =AI7*$AJ$3 -> 17151.074 | AP7: 2 Br - 2 Ba | AQ7: 118 | AR7: 3192.5 | AS7: 0.1 | AT7: =AR7*(1+AS7) -> 3511.75 | AW7: Building 4 | AX7: 3 | AY7: 3 | AZ7: =AY7*AX7 -> 9 | BA7: =275 -> 275 | BB7: =BA7*AZ7 -> 2475 | BE7: A2B | BF7: 66 | BG7: 2 | BH7: 2 | BI7: 8 | BJ7: 3 | BK7: =BJ7*BI7 -> 24
A8: Bldg. SF | B8: 422635 | D8: Totals | E8: 390 | F8: 1 | H8: Totals | I8: 10 | J8: 390 | K8: 178 | L8: 49 | M8: 115 | N8: 48 | O8: 426549 | P8: Gym | Q8: 2 | S8: Lightweight | T8: 261305.65 | U8: SF | AA8: Southeast | AB8: =21*2+14*8+8*12+7*8 -> 306 | AJ8: =SUM(AJ4:AJ7) -> 258371.69 | AK8: sf | AP8: 3 Br - 2 Ba | AQ8: 49 | AR8: 3192.5 | AS8: 0.2 | AT8: =AR8*(1+AS8) -> 3831 | AW8: Building 5 | AX8: 2 | AY8: 2 | AZ8: =AY8*AX8 -> 4 | BA8: 275 | BB8: =BA8*AZ8 -> 1100 | BE8: B2A | BF8: 45 | BG8: 2 | BH8: 1 | BI8: 6 | BJ8: 3 | BK8: =BJ8*BI8 -> 18
A9: Acres | B9: 15.826 | D9: Parking | P9: Iron Rail | Q9: 3074.7 | R9: LF | S9: Pavers | T9: 900 | U9: SF | AA9: More | AB9: =21*4+8*6 -> 132 | AC9: =SUM(AB5:AB9) -> 892 | AJ9: =AJ8/9 -> 28707.965 | AK9: sy | AP9: Totals | AQ9: =SUM(AQ4:AQ8) -> 390 | AT9: =SUMPRODUCT(AQ4:AQ8,AT4:AT8)/AQ9 -> 3369.3154 | BB9: =SUM(BB4:BB8) -> 17050 | BE9: B2B | BF9: 68 | BG9: 2 | BH9: 2 | BI9: 107 | BJ9: 3 | BK9: =BJ9*BI9 -> 321
A10: Site SF | B10: 689380.56 | D10: Garage Parking | F10: 0 | P10: Roofing | Q10: 1734.0111 | R10: Square | S10: Pool Deck | T10: 7964 | U10: SF | AT10: =AT9-AR8 -> 176.81538 | BE10: B2C | BF10: 44 | BG10: 2 | BH10: 1 | BI10: 43 | BJ10: 6 | BK10: =BJ10*BI10 -> 258
A11: Buildings | B11: 4 | D11: Cover Parking | F11: 375 | P11: Stucco | Q11: 28186.002 | R11: Square Yard | S11: Pool Fence | T11: 372 | U11: LF | V11: Corridor Bldg. 1 | W11: 19288 | X11: SF | AA11: Building 2 & 5 | AE11: Building 4 | AF11: =14*8 -> 112 | AT11: =AT10/AR8 -> 0.055384615 | BE11: A3A | BF11: 48 | BG11: 3 | BH11: 2 | BI11: 3 | BJ11: 4 | BK11: =BJ11*BI11 -> 12
A12: Reports Available | D12: Open Parking | F12: 320 | P12: Liav GSF | Q12: 329873 | R12: SF | S12: Dog Park Fence | T12: 400 | U12: LF | V12: Corridor Bldg. 2 | W12: 2159 | X12: SF | AA12: Northwest | AF12: =20*8 -> 160 | BE12: B3A | BF12: 55 | BG12: 3 | BH12: 2 | BI12: 45 | BJ12: 4 | BK12: =BJ12*BI12 -> 180
A13: Site Evaluation Report (GCW) | B13: 45062 | D13: Accessible Parking | F13: 16 | P13: Carports | Q13: 375 | R13: Count | S13: Common Bldg. 1 | T13: 7476 | U13: SF | V13: Corridor Bldg. 3 | W13: 20355 | X13: SF | AA13: Southwest | AF13: =8*18 -> 144 | BF13: =SUMPRODUCT(BF3:BF12,BI3:BI12) -> 17473 | BI13: =SUM(BI3:BI12) -> 390 | BK13: =SUM(BK3:BK12) -> 1287
A14: Soils Report (Universal) | B14: 45848 | D14: Private Garages | F14: 0 | J14: TOTAL COST | L14: 79847909 | P14: Stairs Landings | Q14: 47 | R14: Landings | S14: Common Bldg. 2 | T14: 0 | U14: SF | V14: Corridor Bldg. 4 | W14: 2159 | X14: SF | AA14: Northeast | AF14: =7*12 -> 84 | BK14: =(6+7)*2+4 -> 30
A15: Alta Survey (Wallace) | B15: 45583 | D15: Total Parking Provided | F15: 711 | J15: PER UNIT | L15: 204738.23 | P15: Pump House | Q15: 1 | R15: EA | S15: Common Bldg. 3 | T15: 1888 | U15: SF | V15: TOTAL | W15: 43961 | X15: SF | AA15: Southeast | AB15: =21*2+14*2+8*6+7*6 -> 160 | AC15: =AB15*2 -> 320 | AF15: =SUM(AF11:AF14) -> 500 | BK15: 7 | BL15: 10
A16: Plans | B16: 45825 | D16: Parking Ratio | F16: 1.8230769 | J16: PER GSF | L16: 188.92877 | P16: Lock Boxes | Q16: 10 | R16: EA | S16: Common Bldg. 4 | T16: 1557 | U16: SF | V16: BBQ | W16: 8 | X16: Count | BK16: 13 | BL16: 6
A17: NVE Planning Memo | B17: 45043 | P17: Awning Small | Q17: 58 | R17: EA | S17: Common Bldg. 5 | T17: 0 | U17: SF | V17: Fire Pumps | W17: 1 | X17: Count | AA17: B1B Railings | AB17: =12.5*62 -> 775 | BK17: 22 | BL17: 3
P18: Awning Large | Q18: 10 | R18: EA | S18: HVAC ADD Count | T18: 135.25641 | V18: Asphalt | W18: 256408.47 | BL18: =BK13+BK14+BK15+BK16+BK17+BL15+BL16+BL17 -> 1378
A19: Description | B19: Cost Code | C19: Cost Category | D19: Sub job | E19: Source | F19: Unit Meas. | G19: QTY | H19: Unit Cost | I19: Escalation % | J19: T. Unit Cost | K19: Sub Total | L19: Total | M19: Description / Details | BL19: =BL18*368 -> 507104
A20: General Requirements | B20: 01 | L20: 3849810.3
A21: General Requirements | B21: 01 | C21: S | F21: Mo | G21: 26 | H21: 148069.63 | I21: 0 | J21: 148069.63 | K21: 3849810.3 | AX21: Slab | AY21: Lightweight | AZ21: Roofing
A22: Existing Conditions | B22: 02 | L22: 12000 | AW22: Building 1 | AX22: 59487.01 | AY22: =58247.42+58464.84 -> 116712.26 | AZ22: =62310.84+10234.24 -> 72545.08 | BE22: 15 | BG22: 2
A23: Potholing | B23: 02-3213 | C23: S | D23: ON-SITE | E23: Allowance | G23: 1 | H23: 12000 | I23: 0 | J23: 12000 | K23: 12000 | AW23: Building 2 | AX23: 11996.7 | AY23: 11552.49 | AZ23: =12091.16+2030.7 -> 14121.86 | BE23: 5 | BG23: 2
A24: Concrete | B24: 03 | L24: 2546599.2 | AW24: Building 3 | AX24: 61844.96 | AY24: =60632.4+60507.06 -> 121139.46 | AZ24: =62164.89+10362.59 -> 72527.48 | BE24: 8 | BG24: 3
A25: Slabs | B25: 03-3101 | C25: S | D25: BUILDING | E25: Torrey Pines | F25: SF | G25: 145399.85 | H25: 11.5 | I25: 0 | J25: 11.5 | K25: 1672098.3 | M25: Proposal from NRC at $9.16. Conversation with NRC said he would at $11 to 11.50 if he wasn't aggressive. | AW25: Building 4 | AX25: 12071.18 | AY25: 11901.44 | AZ25: =12174.39+2032.3 -> 14206.69 | BE25: 22 | BG25: 1
A26: Deepened Footings | B26: 03-3101 | C26: S | D26: BUILDING | E26: N/A | J26: 0 | K26: 0 | AW26: Total | AX26: =SUM(AX22:AX25) -> 145399.85 | AY26: =SUM(AY22:AY25) -> 261305.65 | AZ26: =SUM(AZ22:AZ25) -> 173401.11 | BE26: 8 | BG26: 1
A27: Concrete Slab Repairs | B27: 03-3101 | C27: RR | D27: BUILDING | E27: Allowance | F27: LS | G27: 1 | H27: 7500 | I27: 0 | J27: 7500 | K27: 7500 | AF27: =1800+1350+1350+360+900+360+900+1080+360+450 -> 8910
A28: Pump House Concrete | B28: 03-3101 | C28: S | D28: PUMPHOUSE | E28: Allowance | F28: LS | G28: 1 | H28: 10000 | I28: 0 | J28: 10000 | K28: 10000
A29: Trash Enclosure Concrete | B29: 03-3102 | C29: S | D29: OTHER SITE | E29: Bruner | F29: Count | G29: 14 | H29: 5500 | I29: 0 | J29: 5500 | K29: 77000
A30: Pool Area Shower Concrete | B30: 03-3105 | C30: S | D30: POOL AREA | E30: Allowance | F30: LS | G30: 1 | H30: 2500 | I30: 0 | J30: 2500 | K30: 2500
A31: Cabana Concrete | B31: 03-3107 | C31: S | D31: POOL AREA | E31: Allowance | F31: LS | G31: 1 | H31: 23500 | I31: 0 | J31: 23500 | K31: 23500 | AA31: Railings | AD31: Length Ea | AE31: Bldg 1 | AF31: Bldg 2 | AG31: Bldg 3 | AH31: Bldg 4 | AI31: Bldg 5
A32: Pool Equipment Foundation | B32: 03-3108 | C32: S | D32: POOL EQUIP | E32: Allowance | F32: LS | G32: 1 | H32: 4000 | I32: 0 | J32: 4000 | K32: 4000 | AB32: Outside Corner Units | AD32: =(21+15) -> 36 | AE32: =AD32*7*2 -> 504 | AF32: =AD32*2 -> 72 | AG32: =AD32*7 -> 252 | AH32: =AD32*8 -> 288 | AI32: 0
A33: Lightweight Concrete | B33: 03-3116 | C33: S | D33: BUILDING | E33: Bruner | F33: SF | G33: 261305.65 | H33: 2.6 | I33: 0 | J33: 2.6 | K33: 679394.69 | M33: NV Gypsum proposal at Bruner. | AB33: Inside Corner Units | AD33: 13 | AE33: =AD33*10*2 -> 260 | AF33: N/A | AG33: 260 | AH33: N/A | AI33: N/A | AL33: =AG33+AE33 -> 520
A34: Deck Concrete | B34: 03-5001 | C34: S | D34: BUILDING | E34: Bruner | F34: SF | G34: 3440 | H34: 20.525068 | I34: 0 | J34: 20.525068 | K34: 70606.233 | AB34: Small Railings | AD34: 8 | AE34: =AD34*52 -> 416 | AF34: =AD34*12 -> 96 | AG34: =AD34*28 -> 224 | AH34: =AD34*30 -> 240 | AI34: 0 | AL34: =AL33/AJ35 -> 0.19908116
A35: Parking Garage | B35: 03-G | L35: 0 | AE35: =SUM(AE32:AE34) -> 1180 | AF35: =SUM(AF32:AF34) -> 168 | AG35: =SUM(AG32:AG34) -> 736 | AH35: =SUM(AH32:AH34) -> 528 | AI35: =SUM(AI32:AI34) -> 0 | AJ35: =SUM(AE35:AI35) -> 2612
A36: Parking Garage Structure | C36: S | E36: N/A | G36: 0 | J36: 0 | K36: 0
A37: Core Slab Precast Concrete | C37: S | E37: N/A | J37: 0 | K37: 0 | AA37: Lightweight | AE37: Bldg 1 | AF37: Bldg 2 | AG37: Bldg 3 | AH37: Bldg 4 | AI37: Bldg 5
A38: Concrete Slab on Grade | C38: S | E38: N/A | J38: 0 | K38: 0 | AB38: Level 2 | AD38: SF | AE38: =62029-860-2726 -> 58443 | AF38: =12359-669 -> 11690 | AG38: =64481-860-2888 -> 60733 | AH38: =12359-669 -> 11690 | AI38: 0
A39: Concrete Topping Slab 4" / Level | C39: S | E39: N/A | J39: 0 | K39: 0 | AB39: Level 3 | AD39: SF | AE39: =62109-860-2827 -> 58422 | AF39: N/A | AG39: 60733 | AH39: N/A | AI39: 0
A40: Electrical | C40: S | E40: N/A | J40: 0 | K40: 0 | AB40: Total | AD40: SF | AE40: =SUM(AE38:AE39) -> 116865 | AF40: =SUM(AF38:AF39) -> 11690 | AG40: =SUM(AG38:AG39) -> 121466 | AH40: =SUM(AH38:AH39) -> 11690 | AI40: =SUM(AI38:AI39) -> 0 | AJ40: =SUM(AE40:AI40) -> 261711
...

Sheet Insurance_Bonds
A1: West Henderson | U1: Contractor Insurance and Bonds
B8: Contractor General Liability Insurance | K8: P&P Bond
B10: Underlying Policy (First $1 mm) | K10: Months of Construction | M10: 18
B11: Rate (per $1,000 of Contractor Revenue) | E11: 3.7395 | K11: Total Hard Costs | M11: 77376748
B12: Total GC Contract | E12: 77376748
B13: Subtotal | E13: =E11/1000*E12 -> 289350.35
B14: Fees/Taxes/Possible Increases | E14: =E13*F14 -> 22424.652 | F14: 0.0775 | K14: Basic Rate Table
B15: Total Insurance | E15: =E13+E14 -> 311775 | Q15: Total
M16: Rate Per $K | N16: Contract Price | O16: Base Rate | P16: Surcharge | Q16: Premium
B17: Umbrella Policy ($20 mm Excess Coverage) | K17: First | L17: 100000 | M17: 14.4 | N17: 100000 | O17: =+N17/1000*M17 -> 1440 | P17: =IF(O17>0,IF((M10-12)>0,(M10-12)*0.01,"0"),"0") -> 0.06 | Q17: =IF((M10-12)>0,(1+P17)*O17,O17) -> 1526.4
B18: Rate (per $1,000 of Contractor Revenue) | E18: 3.996 | K18: Next | L18: 400000 | M18: 13.68 | N18: 400000 | O18: =+N18/1000*M18 -> 5472 | P18: =IF(O18>0,IF((M10-12)>0,(M10-12)*0.01,"0"),"0") -> 0.06 | Q18: =IF((M10-12)>0,(1+P18)*O18,O18) -> 5800.32
B19: Total GC Contract | E19: =E12 -> 77376748 | K19: Next | L19: 2000000 | M19: 8.7 | N19: 2000000 | O19: =+N19/1000*M19 -> 17400 | P19: =IF(O19>0,IF((M10-12)>0,(M10-12)*0.01,"0"),"0") -> 0.06 | Q19: =IF((M10-12)>0,(1+P19)*O19,O19) -> 18444
B20: Subtotal | E20: =E18/1000*E19 -> 309197.48 | K20: Next | L20: 2500000 | M20: 6.9 | N20: 2500000 | O20: =+N20/1000*M20 -> 17250 | P20: =IF(O20>0,IF((M10-12)>0,(M10-12)*0.01,"0"),"0") -> 0.06 | Q20: =IF((M10-12)>0,(1+P20)*O20,O20) -> 18285
B21: Fees/Taxes/Possible Increases | E21: =E20*F21 -> 18551.849 | F21: 0.06 | K21: Next | L21: 2500000 | M21: 6.3 | N21: 2500000 | O21: =+N21/1000*M21 -> 15750 | P21: =IF(O21>0,IF((M10-12)>0,(M10-12)*0.01,"0"),"0") -> 0.06 | Q21: =IF((M10-12)>0,(1+P21)*O21,O21) -> 16695
B22: Total Umbrella | E22: =E20+E21 -> 327749.33 | K22: Next | L22: 2500000 | M22: 5.76 | N22: =+M11-SUM(N17:N21) -> 69876748 | O22: =+N22/1000*M22 -> 402490.07 | P22: =IF(O22>0,IF((M10-12)>0,(M10-12)*0.01,"0"),"0") -> 0.06 | Q22: =IF((M10-12)>0,(1+P22)*O22,O22) -> 426639.47
K23: Over | L23: 10000000 | M23: 5.76 | O23: =+N23/1000*M23 -> 0 | P23: =IF(O23>0,IF((M10-12)>0,(M10-12)*0.01,"0"),"0") -> 0 | Q23: =IF((M10-12)>0,(1+P23)*O23,O23) -> 0
B24: Total GL Insurance | E24: =E15+E22 -> 639524.33 | M24: Totals | N24: =SUM(N17:N23) -> 77376748 | O24: =SUM(O17:O23) -> 459802.07 | Q24: =SUM(Q17:Q23) -> 487390.19
B26: Annual Policy Inflation | E26: 0.1
B30: % Completed by Year
F31: Policy Allocation | K31: Sub Bonds
B32: Year | E32: % Completed | F32: Pre-Inflation | G32: Post-Inflation | K32: Sub Bonds % | M32: ='[83]Level 1.1 UPDATE B'!G327 -> 0.013
B33: 1 | E33: 0.85921962 | F33: =E33*$E$24 -> 549491.85 | G33: =F33*(1+$E$26)^(B33-1) -> 549491.85 | K33: Applicable Costs* | M33: =SUM('[84]Level 1.1'!L16:L286) -> 27580796
B34: 2 | E34: 0.14078038 | F34: =E34*$E$24 -> 90032.482 | G34: =F34*(1+$E$26)^(B34-1) -> 99035.73 | K34: Sub Bonds | M34: =M32*M33 -> 358550.35
B35: 3 | E35: 0 | F35: =E35*$E$24 -> 0 | G35: =F35*(1+$E$26)^(B35-1) -> 0 | K35: *Hard Costs excluding FF&E, Contingency, Insurance, Contractor Fee, and General Requirements
D36: Total GL Insurance | F36: =SUM(F33:F35) -> 639524.33 | G36: =SUM(G33:G35) -> 648527.58
B42: Summary of Contractor Insurance and Bonds
E43: Include In Budget | F43: Budget
B44: Contractor General Liability Insurance | D44: =G36 -> 648527.58 | E44: x | F44: =IF(E44="x",D44,0) -> 648527.58
B45: P&P Bond | D45: =Q24 -> 487390.19 | F45: =IF(E45="x",D45,0) -> 0
B46: Sub Bonds | D46: =M34 -> 358550.35 | E46: x | F46: =IF(E46="x",D46,0) -> 358550.35
B47: Subtotal | D47: =SUM(D44:D46) -> 1494468.1 | F47: =SUM(F44:F46) -> 1007077.9

Sheet Level 3
A1: Project Details | D1: Unit Breakdown | H1: Breakdown Per Building | P1: List of Take offs | S1: List of Take offs | V1: List of Take offs
A2: Project | B2: West Henderson | D2: Unit Type | E2: Number | F2: % | H2: Bldg. | I2: Levels | J2: Unit | K2: 1 Br - 1 Ba | L2: 2 Br - 1 Ba | M2: 2 Br - 2 Ba | N2: 3 Br - 2 Ba | O2: GSF | P2: Slab SF | Q2: 145399.85 | R2: GSF (Provided in Matrix) | S2: 1 Br - 1 Ba Counter | T2: =(14.42+12.35+13.12+11.52)*K8 -> 9150.98 | U2: SF | V2: Structural | W2: 59616.52
A3: Budget Level | B3: Level 3 | D3: Studios | E3: 0 | F3: =E3/$E$8 -> 0 | H3: 1 | I3: 3 | J3: =SUM(K3:N3) -> 169 | K3: =29*3 -> 87 | L3: 17 | M3: 48 | N3: 17 | O3: 185300 | P3: Elevators | Q3: 4 | R3: Count | S3: 2 Br - 1 Ba Counter | T3: =L8*(43.46+3.6+7.5) -> 2673.44 | U3: SF | V3: Corridor Bldg. 1 | W3: =3808+3514+3590+3041+2630+2705 -> 19288 | X3: SF
A4: Product | B4: Affordable | D4: 1 Br - 1 Ba | E4: =K8 -> 178 | F4: =E4/$E$8 -> 0.45641026 | H4: 2 | I4: 2 | J4: =SUM(K4:N4) -> 24 | K4: 9 | L4: 7 | M4: 8 | N4: 0 | O4: 24353 | P4: Elevators Stops | Q4: =Q3*3 -> 12 | R4: Count | S4: 2 Br - 2 Ba Counter | T4: =(13+13+12+12.5+6.3)*6+(8.5+16+13+7+11)*46 -> 2893.8 | U4: SF | V4: Corridor Bldg. 2 | W4: =1077+1082 -> 2159 | X4: SF
A5: UPDATED | B5: 46020 | D5: 2 Br - 1 Ba | E5: =L8 -> 49 | F5: =E5/$E$8 -> 0.12564103 | H5: 3 | I5: 3 | J5: 173 | K5: 73 | L5: 18 | M5: 51 | N5: 31 | O5: 192543 | P5: Trash Encl. | Q5: 13 | R5: Provided in Site Plan | S5: 3 Br - 2 Ba Counter | T5: =(15+7+4+16.82+31)*N8 -> 3543.36 | U5: SF | V5: Corridor Bldg. 3 | W5: =3955+3726+3726+3298+2825+2825 -> 20355 | X5: SF
A6: Timeline | B6: 26 | D6: 2 Br - 2 Ba | E6: =M8 -> 115 | F6: =E6/$E$8 -> 0.29487179 | H6: 4 | I6: 2 | J6: 24 | K6: 9 | L6: 7 | M6: 8 | N6: 0 | O6: 24353 | P6: Stairs | Q6: =6+7+4 -> 17 | R6: Count | S6: 1x1 Decks | T6: =86*20*2 -> 3440 | U6: SF | V6: Corridor Bldg. 4 | W6: =1077+1082 -> 2159 | X6: SF
A7: Floors | B7: 2 & 3 Levels | D7: 3 Br - 2 Ba | E7: =N8 -> 48 | F7: =E7/$E$8 -> 0.12307692 | P7: Pool | Q7: 1 | S7: 2x1 Decks | U7: SF | V7: TOTAL | W7: =SUM(W3:W6) -> 43961 | X7: SF
A8: Bldg. SF | B8: 422635 | D8: Totals | E8: =SUM(E3:E7) -> 390 | F8: =E8/$E$8 -> 1 | H8: Totals | I8: =SUM(I3:I7) -> 10 | J8: =SUM(J3:J7) -> 390 | K8: =SUM(K3:K7) -> 178 | L8: =SUM(L3:L7) -> 49 | M8: =SUM(M3:M7) -> 115 | N8: =SUM(N3:N7) -> 48 | O8: =SUM(O3:O7) -> 426549 | P8: Gym | Q8: 2 | S8: Lightweight | T8: 261305.65 | U8: SF | V8: BBQ | W8: 8 | X8: Count
A9: Acres | B9: 15.826 | D9: Parking | P9: Iron Rail | Q9: 3228 | R9: LF | S9: Pavers | T9: 900 | U9: SF | V9: Fire Pumps | W9: 1 | X9: Count
A10: Site SF | B10: =B9*43560 -> 689380.56 | D10: Garage Parking | F10: 0 | P10: Roofing | Q10: 1734.0111 | R10: Square | S10: Pool Deck | T10: =10114-1655-215-35*8 -> 7964 | U10: SF | V10: Asphalt Onsite | W10: 243608.62
A11: Buildings | B11: 4 | D11: Cover Parking | F11: 375 | P11: Stucco | Q11: 28186.002 | R11: Square Yard | S11: Pool Fence | T11: 372 | U11: LF | V11: Asphalt Offsite | W11: 145460
A12: Reports Available | D12: Open Parking | F12: 320 | P12: GSF | Q12: 329873 | R12: SF | S12: Dog Park Fence | T12: =200*2 -> 400 | U12: LF
A13: Site Evaluation Report (GCW) | B13: 45062 | D13: Accessible Parking | F13: 16 | P13: Carports | Q13: =F11 -> 375 | R13: Count | S13: Common Bldg. 1 | T13: 7476 | U13: SF
A14: Soils Report (Universal) | B14: 45848 | D14: Private Garages | F14: 0 | J14: TOTAL COST | L14: =L321 -> 77376748 | P14: Stairs Landings | Q14: =4*2+13*3 -> 47 | R14: Landings | S14: Common Bldg. 2 | T14: 0 | U14: SF
A15: Alta Survey (Wallace) | B15: 45583 | D15: Total Parking Provided | F15: =SUM(F10:F14) -> 711 | J15: PER UNIT | L15: =L14/E8 -> 198401.92 | P15: Pump House | Q15: 1 | R15: EA | S15: Common Bldg. 3 | T15: =748+1140 -> 1888 | U15: SF
A16: Plans | B16: 45938 | D16: Parking Ratio | F16: =SUM(F10:F13)/E8 -> 1.8230769 | J16: PER GSF | L16: =L14/B8 -> 183.08173 | P16: Lock Boxes | Q16: 10 | R16: EA | S16: Common Bldg. 4 | T16: 1557 | U16: SF
A17: NVE Planning Memo | B17: 45043 | P17: Awning Small | Q17: 58 | R17: EA | S17: Common Bldg. 5 | T17: 0 | U17: SF
P18: Awning Large | Q18: 10 | R18: EA | S18: HVAC ADD Count | T18: =(E6*250+E7*500)/E8 -> 135.25641
A19: Description | B19: Cost Code | C19: Cost Category | D19: Sub job | E19: Source | F19: Unit Meas. | G19: QTY | H19: Unit Cost | I19: Esc. % | J19: T. Unit Cost | K19: Sub Total | L19: Total | M19: Description / Details
A20: General Requirements | B20: 01 | C20: S | I20: 0.06 | K20: =I20*SUM(K22:K308,K311) -> 3857213.7
A21: General Requirements | B21: 01 | L21: =K20 -> 3857213.7
A22: Potholing | B22: 02-3213 | C22: S | D22: ON-SITE | E22: Allowance | G22: 1 | H22: 12000 | I22: 0 | J22: =H22*(1+I22) -> 12000 | K22: =J22*G22 -> 12000
A23: Existing Conditions | B23: 02 | L23: =K22 -> 12000
A24: Slabs | B24: 03-3101 | C24: S | D24: BUILDING | E24: Proposal | F24: SF | G24: =Q2 -> 145399.85 | H24: 9.5 | I24: 0 | J24: =H24*(1+I24) -> 9.5 | K24: =J24*G24 -> 1381298.6 | M24: Proposal by NRC at $9.16/sf
A25: Deepened Footings | B25: 03-3101 | C25: S | D25: BUILDING | E25: N/A | J25: =H25*(1+I25) -> 0 | K25: =J25*G25 -> 0
A26: Concrete Slab Repairs | B26: 03-3101 | C26: RR | D26: BUILDING | E26: Allowance | F26: LS | G26: 1 | H26: =2500*3 -> 7500 | I26: 0 | J26: =H26*(1+I26) -> 7500 | K26: =J26*G26 -> 7500
A27: Pump House Concrete | B27: 03-3101 | C27: S | D27: PUMPHOUSE | E27: Allowance | F27: LS | G27: 1 | H27: 10000 | I27: 0 | J27: =H27*(1+I27) -> 10000 | K27: =J27*G27 -> 10000
A28: Trash Enclosure Concrete | B28: 03-3102 | C28: S | D28: OTHER SITE | E28: Bruner | F28: Count | G28: 14 | H28: 5500 | I28: 0 | J28: =H28*(1+I28) -> 5500 | K28: =J28*G28 -> 77000
A29: Pool Area Shower Concrete | B29: 03-3105 | C29: S | D29: POOL AREA | E29: Allowance | F29: LS | G29: =$Q$7 -> 1 | H29: 2500 | I29: 0 | J29: =H29*(1+I29) -> 2500 | K29: =J29*G29 -> 2500
A30: Cabana Concrete | B30: 03-3107 | C30: S | D30: POOL AREA | E30: Allowance | F30: LS | G30: 1 | H30: 35000 | I30: 0 | J30: =H30*(1+I30) -> 35000 | K30: =J30*G30 -> 35000 | M30: Added $15k for sunken seating at pool area courtyard
A31: Pool Equipment Foundation | B31: 03-3108 | C31: S | D31: POOL EQUIP | E31: Allowance | F31: LS | G31: 1 | H31: 7500 | I31: 0 | J31: =H31*(1+I31) -> 7500 | K31: =J31*G31 -> 7500
A32: Lightweight Concrete | B32: 03-3116 | C32: S | D32: BUILDING | E32: Bruner | F32: SF | G32: =T8 -> 261305.65 | H32: 2.6 | I32: 0 | J32: =H32*(1+I32) -> 2.6 | K32: =J32*G32 -> 679394.69
A33: Deck Concrete | B33: 03-5001 | C33: S | D33: BUILDING | E33: Bruner | F33: SF | G33: =SUM($T$6:$T$7) -> 3440 | H33: 20.525068 | I33: 0 | J33: =H33*(1+I33) -> 20.525068 | K33: =J33*G33 -> 70606.233
A34: Concrete | B34: 03 | L34: =SUM(K24:K33) -> 2270799.5
A35: Elevator Shaft | B35: 04-2201 | C35: S | D35: BUILDING | E35: Bruner | F35: Per Stop | G35: =4*3 -> 12 | H35: 14000 | I35: 0 | J35: =H35*(1+I35) -> 14000 | K35: =J35*G35 -> 168000 | M35: Elevator shaf plus elevator pits.
A36: Trash Enclosure | B36: 04-2202 | C36: S | D36: OTHER SITE | E36: Bruner | F36: Count | G36: 14 | H36: 6500 | I36: 0 | J36: =H36*(1+I36) -> 6500 | K36: =J36*G36 -> 91000
A37: Masonry Veneer | B37: 04-4301 | C37: S | D37: ON-SITE | E37: Allowance | F37: LS | G37: 1 | J37: =H37*(1+I37) -> 0 | K37: =J37*G37 -> 0
A38: Masonry Veneer Pool Area | B38: 04-4305 | C38: S | D38: POOL AREA | E38: Allowance | F38: LS | G38: 4 | H38: 10000 | I38: 0 | J38: =H38*(1+I38) -> 10000 | K38: =J38*G38 -> 40000
A39: Pool Eq. Shower Stone | B39: 04-4306 | C39: A | D39: POOL EQUIP | E39: Allowance | F39: LS | G39: =$Q$7 -> 1 | H39: 15000 | I39: 0 | J39: =H39*(1+I39) -> 15000 | K39: =J39*G39 -> 15000
A40: Masonry | B40: 04 | L40: =SUM(K35:K39) -> 314000
...

Sheet Summary Changes
A2: Line Item | B2: Level 2 | C2: Level 3 | D2: Variance | E2: Comments
A3: Slab Concrete | B3: ='Level 2 - Transmitted (2)'!K25 -> 1672098.3 | C3: ='Level 3'!K24 -> 1381298.6 | D3: =B3-C3 -> 290799.7 | E3: Increased unit cost $11.50 to average of 3 proposals $11.83. Recommend leaving at $11.50
A4: ='Level 2 - Transmitted (2)'!A45 -> Elevator Shaft | B4: ='Level 2 - Transmitted (2)'!K45 -> 129600 | C4: ='Level 3'!K35 -> 168000 | D4: =B4-C4 -> -38400 | E4: Increase to include elevator pis (CMU)
A5: ='Level 3'!A41 -> Structural Steel | B5: ='Level 2 - Transmitted (2)'!K51 -> 240254.58 | C5: ='Level 3'!K41 -> 298082.6 | D5: =B5-C5 -> -57828.024 | E5: Increased price per pound based on current proposals.
A6: ='Level 3'!A52 -> Framing | B6: ='Comparison to Previous'!K48 -> 7607430 | C6: ='Comparison to Previous'!R48 -> 7487665.3 | D6: =B6-C6 -> 119764.67 | E6: Changed unit cost to average of 3 current proposals
A7: ='Comparison to Previous'!A61 -> Insulation | B7: ='Comparison to Previous'!K61 -> 1056587.5 | C7: ='Comparison to Previous'!R61 -> 1005655 | D7: =B7-C7 -> 50932.5 | E7: Changed unit cost to average of 3 current proposals
A8: ='Level 3'!A117 -> Hall Flooring | B8: ='Comparison to Previous'!K114 -> 217606.95 | C8: ='Level 3'!K117 -> 292500 | D8: =B8-C8 -> -74893.05 | E8: Updated pricing per unit to Bruner (from Torrey Pines)
A9: ='Comparison to Previous'!A148 -> Appliances - Laundry Room | B9: ='Comparison to Previous'!K148 -> 0 | C9: ='Comparison to Previous'!R148 -> 130000 | D9: =B9-C9 -> -130000 | E9: Added a line item to consider cost of laundry room appliances. Considering 2.
A10: ='Comparison to Previous'!A177 -> HVAC Standard | B10: ='Comparison to Previous'!K177 -> 3851250 | C10: ='Comparison to Previous'!R177 -> 4117739.5 | D10: =B10-C10 -> -266489.5 | E10: Change unit cost to average of 2 best proposals vs Bruner.
A11: ='Comparison to Previous'!A180 -> Electrical | B11: ='Comparison to Previous'!K180 -> 4251708.1 | C11: ='Comparison to Previous'!R180 -> 4787239.7 | D11: =B11-C11 -> -535531.57 | E11: Change unit cost to average of 2 best proposals vs Bruner.
A12: ='Comparison to Previous'!A211 -> Mass Grading | B12: ='Comparison to Previous'!K211 -> 876756 | C12: ='Comparison to Previous'!R211 -> 572075 | D12: =B12-C12 -> 304681
A13: ='Comparison to Previous'!A236 -> Entry Security Gates | B13: ='Comparison to Previous'!K236 -> 192000 | C13: ='Comparison to Previous'!R236 -> 100000 | D13: =B13-C13 -> 92000
A14: ='Comparison to Previous'!A246 -> Site Landscaping | B14: ='Comparison to Previous'!K246 -> 3662724.8 | C14: ='Comparison to Previous'!R246 -> 2289198.3 | D14: =B14-C14 -> 1373526.4
A15: ='Comparison to Previous'!A250 -> Offsite Paving | B15: ='Comparison to Previous'!K250 -> 795028.78 | C15: ='Level 3'!H252 -> 1006389.8 | D15: =B15-C15 -> -211361.02
A16: ='Comparison to Previous'!A267 -> Off Site Water | B16: ='Comparison to Previous'!K267 -> 2362698.4 | C16: ='Comparison to Previous'!R267 -> 1635293.3 | D16: =B16-C16 -> 727405.11
A17: ='Comparison to Previous'!A268 -> Off Site Sewer | B17: ='Comparison to Previous'!K268 -> 1073770.8 | C17: ='Comparison to Previous'!R268 -> 436684.18 | D17: =B17-C17 -> 637086.67
A18: ='Comparison to Previous'!A274 -> Solar PV System | B18: ='Comparison to Previous'!K274 -> 399750 | C18: ='Comparison to Previous'!R274 -> 1567975.9 | D18: =B18-C18 -> -1168225.9
A19: ='Comparison to Previous'!A289 -> Bid Risk | B19: ='Comparison to Previous'!K289 -> 1254667.1 | C19: ='Comparison to Previous'!R289 -> 632953.91 | D19: =B19-C19 -> 621713.23
D20: =B20-C20 -> 0
A21: Total | D21: =SUM(D3:D20) -> 1735180.3

Sheet Comparison to Previous
A1: WEST HENDERSON | C1: Level 1 | F1: Level 1 (New Site Plan) A | K1: Level 2 | R1: Level 3
C3: Details | F3: Details | H3: Change | I3: % | K3: Details | R3: Details | T3: Change | U3: %
C4: Buildings | D4: 5 | F4: Buildings | G4: 4 | H4: =D4-G4 -> 1 | I4: =H4/D4 -> 0.2 | K4: Buildings | L4: 4 | R4: Buildings | S4: 4 | T4: =L4-S4 -> 0 | U4: =T4/L4 -> 0
C5: Bldg. SF | D5: 431911 | F5: Bldg. SF | G5: ='Level 1.1 UPDATE A'!B8 -> 426549 | H5: =D5-G5 -> 5362 | I5: =H5/D5 -> 0.012414595 | K5: Bldg. SF | L5: ='Level 1.1 UPDATE B'!B8 -> 426549 | R5: Bldg. SF | S5: ='Level 3'!B8 -> 422635 | T5: =L5-S5 -> 3914 | U5: =T5/L5 -> 0.0091759681
C6: Unit Count | D6: ='Level 1'!$E$8 -> 390 | F6: Unit Count | G6: ='Level 1'!$E$8 -> 390 | H6: =D6-G6 -> 0 | I6: =H6/D6 -> 0 | K6: Unit Count | L6: ='Level 1'!$E$8 -> 390 | R6: Unit Count | S6: ='Level 3'!J8 -> 390 | T6: =L6-S6 -> 0 | U6: =T6/L6 -> 0
C8: TOTAL COST | D8: =D317 -> 84590981 | F8: TOTAL COST | G8: =G317 -> 82551538 | H8: =D8-G8 -> 2039443 | I8: =H8/D8 -> 0.024109461 | K8: TOTAL COST | L8: =L317 -> 79847909 | R8: TOTAL COST | S8: =S317 -> 77376748 | T8: =L8-S8 -> 2471161.1 | U8: =T8/L8 -> 0.030948351
C9: PER GSF | D9: =D8/D5 -> 195.85281 | F9: PER GSF | G9: =G8/G5 -> 193.53354 | H9: =D9-G9 -> 2.3192652 | I9: =H9/D9 -> 0.011841879 | K9: PER GSF | L9: =L8/L5 -> 187.19516 | R9: PER GSF | S9: =S8/S5 -> 183.08173 | T9: =L9-S9 -> 4.1134294 | U9: =T9/L9 -> 0.021974016
C10: PER UNIT | D10: =D8/D6 -> 216899.95 | F10: PER UNIT | G10: =G8/G6 -> 211670.61 | H10: =D10-G10 -> 5229.341 | I10: =H10/D10 -> 0.024109461 | K10: PER UNIT | L10: =L8/L6 -> 204738.23 | R10: PER UNIT | S10: =S8/S6 -> 198401.92 | T10: =L10-S10 -> 6336.3105 | U10: =T10/L10 -> 0.030948351
H13: Conditions | I13: Conditions | N13: Conditions | P13: Conditions | T13: Conditions | U13: Conditions
H14: 50000 | I14: 0.05 | N14: 50000 | P14: 0.05 | T14: 50000 | U14: 0.05
A15: Description | C15: Sub Total | D15: Total | F15: Sub Total | G15: Total | H15: PV$ | I15: PV% | K15: Sub Total | L15: Total | N15: PV$ | P15: PV% | R15: Sub Total | S15: Total | T15: PV$ | U15: PV%
A16: General Requirements | C16: ='Level 1'!K21 -> 4240149 | F16: =VLOOKUP(A16,'Level 1.1 UPDATE A'!$A$21:$K$292,11,FALSE) -> 4080000 | H16: =C16-F16 -> 160149 | I16: =IF(D16=0,0,H16/D16) -> 0 | K16: =VLOOKUP(A16,'Level 2 - Transmitted (2)'!$A$21:$K$335,11,FALSE) -> 3849810.3 | N16: =C16-K16 -> 390338.7 | P16: =IF(D16=0,0,N16/D16) -> 0 | R16: =VLOOKUP(A16,'Level 3'!$A$20:$K$319,11,FALSE) -> 3857213.7 | T16: =K16-R16 -> -7403.3925 | U16: =IF(K16=0,0,T16/K16) -> -0.0019230539
A17: General Requirements | D17: ='Level 1'!L20 -> 4240149 | G17: =VLOOKUP(A17,'Level 1.1 UPDATE A'!$A$20:$L$330,12,FALSE) -> 4080000 | H17: =D17-G17 -> 160149 | I17: =IF(D17=0,0,H17/D17) -> 0.037769663 | L17: =K16 -> 3849810.3 | N17: =D17-L17 -> 390338.7 | P17: =IF(D17=0,0,N17/D17) -> 0.092057778 | S17: =VLOOKUP(A17,'Level 3'!$A$21:$L$320,12,FALSE) -> 3857213.7 | T17: =L17-S17 -> -7403.3925 | U17: =IF(K17=0,0,T17/K17) -> 0
A18: Potholing | C18: ='Level 1'!K23 -> 12000 | F18: =VLOOKUP(A18,'Level 1.1 UPDATE A'!$A$21:$K$292,11,FALSE) -> 12000 | H18: =C18-F18 -> 0 | I18: =IF(D18=0,0,H18/D18) -> 0 | K18: =VLOOKUP(A18,'Level 2 - Transmitted (2)'!$A$20:$K$335,11,FALSE) -> 12000 | N18: =C18-K18 -> 0 | P18: =IF(D18=0,0,N18/D18) -> 0 | R18: =VLOOKUP(A18,'Level 3'!$A$20:$K$319,11,FALSE) -> 12000 | T18: =K18-R18 -> 0 | U18: =IF(K18=0,0,T18/K18) -> 0
A19: Existing Conditions | D19: ='Level 1'!L22 -> 12000 | G19: =VLOOKUP(A19,'Level 1.1 UPDATE A'!$A$20:$L$330,12,FALSE) -> 12000 | H19: =D19-G19 -> 0 | I19: =IF(D19=0,0,H19/D19) -> 0 | L19: =K18 -> 12000 | N19: =D19-L19 -> 0 | P19: =IF(D19=0,0,N19/D19) -> 0 | S19: =VLOOKUP(A19,'Level 3'!$A$21:$L$320,12,FALSE) -> 12000 | T19: =L19-S19 -> 0 | U19: =IF(K19=0,0,T19/K19) -> 0
A20: Slabs | C20: ='Level 1'!K25 -> 2063622.9 | F20: =VLOOKUP(A20,'Level 1.1 UPDATE A'!$A$21:$K$292,11,FALSE) -> 1795622.4 | H20: =C20-F20 -> 268000.48 | I20: =IF(D20=0,0,H20/D20) -> 0 | K20: =VLOOKUP(A20,'Level 2 - Transmitted (2)'!$A$20:$K$335,11,FALSE) -> 1672098.3 | N20: =C20-K20 -> 391524.6 | P20: =IF(D20=0,0,N20/D20) -> 0 | R20: =VLOOKUP(A20,'Level 3'!$A$20:$K$319,11,FALSE) -> 1381298.6 | T20: =K20-R20 -> 290799.7 | U20: =IF(K20=0,0,T20/K20) -> 0.17391304
A21: Deepened Footings | C21: ='Level 1'!K26 -> 0 | F21: =VLOOKUP(A21,'Level 1.1 UPDATE A'!$A$21:$K$292,11,FALSE) -> 0 | H21: =C21-F21 -> 0 | I21: =IF(D21=0,0,H21/D21) -> 0 | K21: =VLOOKUP(A21,'Level 2 - Transmitted (2)'!$A$20:$K$335,11,FALSE) -> 0 | N21: =C21-K21 -> 0 | P21: =IF(D21=0,0,N21/D21) -> 0 | R21: =VLOOKUP(A21,'Level 3'!$A$20:$K$319,11,FALSE) -> 0 | T21: =K21-R21 -> 0 | U21: =IF(K21=0,0,T21/K21) -> 0
A22: Concrete Slab Repairs | C22: ='Level 1'!K27 -> 7500 | F22: =VLOOKUP(A22,'Level 1.1 UPDATE A'!$A$21:$K$292,11,FALSE) -> 7500 | H22: =C22-F22 -> 0 | I22: =IF(D22=0,0,H22/D22) -> 0 | K22: =VLOOKUP(A22,'Level 2 - Transmitted (2)'!$A$20:$K$335,11,FALSE) -> 7500 | N22: =C22-K22 -> 0 | P22: =IF(D22=0,0,N22/D22) -> 0 | R22: =VLOOKUP(A22,'Level 3'!$A$20:$K$319,11,FALSE) -> 7500 | T22: =K22-R22 -> 0 | U22: =IF(K22=0,0,T22/K22) -> 0
A23: Pump House Concrete | C23: ='Level 1'!K28 -> 3597 | F23: =VLOOKUP(A23,'Level 1.1 UPDATE A'!$A$21:$K$292,11,FALSE) -> 3597 | H23: =C23-F23 -> 0 | I23: =IF(D23=0,0,H23/D23) -> 0 | K23: =VLOOKUP(A23,'Level 2 - Transmitted (2)'!$A$20:$K$335,11,FALSE) -> 10000 | N23: =C23-K23 -> -6403 | P23: =IF(D23=0,0,N23/D23) -> 0 | R23: =VLOOKUP(A23,'Level 3'!$A$20:$K$319,11,FALSE) -> 10000 | T23: =K23-R23 -> 0 | U23: =IF(K23=0,0,T23/K23) -> 0
A24: Trash Enclosure Concrete | C24: ='Level 1'!K29 -> 38608.5 | F24: =VLOOKUP(A24,'Level 1.1 UPDATE A'!$A$21:$K$292,11,FALSE) -> 38608.5 | H24: =C24-F24 -> 0 | I24: =IF(D24=0,0,H24/D24) -> 0 | K24: =VLOOKUP(A24,'Level 2 - Transmitted (2)'!$A$20:$K$335,11,FALSE) -> 77000 | N24: =C24-K24 -> -38391.5 | P24: =IF(D24=0,0,N24/D24) -> 0 | R24: =VLOOKUP(A24,'Level 3'!$A$20:$K$319,11,FALSE) -> 77000 | T24: =K24-R24 -> 0 | U24: =IF(K24=0,0,T24/K24) -> 0
A25: Pool Area Shower Concrete | C25: ='Level 1'!K30 -> 2500 | F25: =VLOOKUP(A25,'Level 1.1 UPDATE A'!$A$21:$K$292,11,FALSE) -> 2500 | H25: =C25-F25 -> 0 | I25: =IF(D25=0,0,H25/D25) -> 0 | K25: =VLOOKUP(A25,'Level 2 - Transmitted (2)'!$A$20:$K$335,11,FALSE) -> 2500 | N25: =C25-K25 -> 0 | P25: =IF(D25=0,0,N25/D25) -> 0 | R25: =VLOOKUP(A25,'Level 3'!$A$20:$K$319,11,FALSE) -> 2500 | T25: =K25-R25 -> 0 | U25: =IF(K25=0,0,T25/K25) -> 0
A26: Cabana Concrete | C26: ='Level 1'!K31 -> 0 | F26: =VLOOKUP(A26,'Level 1.1 UPDATE A'!$A$21:$K$292,11,FALSE) -> 0 | H26: =C26-F26 -> 0 | I26: =IF(D26=0,0,H26/D26) -> 0 | K26: =VLOOKUP(A26,'Level 2 - Transmitted (2)'!$A$20:$K$335,11,FALSE) -> 23500 | N26: =C26-K26 -> -23500 | P26: =IF(D26=0,0,N26/D26) -> 0 | R26: =VLOOKUP(A26,'Level 3'!$A$20:$K$319,11,FALSE) -> 35000 | T26: =K26-R26 -> -11500 | U26: =IF(K26=0,0,T26/K26) -> -0.4893617
A27: Pool Equipment Foundation | C27: ='Level 1'!K32 -> 0 | F27: =VLOOKUP(A27,'Level 1.1 UPDATE A'!$A$21:$K$292,11,FALSE) -> 0 | H27: =C27-F27 -> 0 | I27: =IF(D27=0,0,H27/D27) -> 0 | K27: =VLOOKUP(A27,'Level 2 - Transmitted (2)'!$A$20:$K$335,11,FALSE) -> 4000 | N27: =C27-K27 -> -4000 | P27: =IF(D27=0,0,N27/D27) -> 0 | R27: =VLOOKUP(A27,'Level 3'!$A$20:$K$319,11,FALSE) -> 7500 | T27: =K27-R27 -> -3500 | U27: =IF(K27=0,0,T27/K27) -> -0.875
A28: Lightweight Concrete | C28: ='Level 1'!K33 -> 754201.14 | F28: =VLOOKUP(A28,'Level 1.1 UPDATE A'!$A$21:$K$292,11,FALSE) -> 769430.34 | H28: =C28-F28 -> -15229.2 | I28: =IF(D28=0,0,H28/D28) -> 0 | K28: =VLOOKUP(A28,'Level 2 - Transmitted (2)'!$A$20:$K$335,11,FALSE) -> 679394.69 | N28: =C28-K28 -> 74806.45 | P28: =IF(D28=0,0,N28/D28) -> 0 | R28: =VLOOKUP(A28,'Level 3'!$A$20:$K$319,11,FALSE) -> 679394.69 | T28: =K28-R28 -> 0 | U28: =IF(K28=0,0,T28/K28) -> 0
A29: Deck Concrete | C29: ='Level 1'!K34 -> 64575.68 | F29: =VLOOKUP(A29,'Level 1.1 UPDATE A'!$A$21:$K$292,11,FALSE) -> 64575.68 | H29: =C29-F29 -> 0 | I29: =IF(D29=0,0,H29/D29) -> 0 | K29: =VLOOKUP(A29,'Level 2 - Transmitted (2)'!$A$20:$K$335,11,FALSE) -> 70606.233 | N29: =C29-K29 -> -6030.5531 | P29: =IF(D29=0,0,N29/D29) -> 0 | R29: =VLOOKUP(A29,'Level 3'!$A$20:$K$319,11,FALSE) -> 70606.233 | T29: =K29-R29 -> 0 | U29: =IF(K29=0,0,T29/K29) -> 0
A30: Concrete | D30: ='Level 1'!L24 -> 2934605.2 | G30: =VLOOKUP(A30,'Level 1.1 UPDATE A'!$A$20:$L$330,12,FALSE) -> 2681833.9 | H30: =D30-G30 -> 252771.28 | I30: =IF(D30=0,0,H30/D30) -> 0.08613468 | L30: =VLOOKUP(A30,'Level 2 - Transmitted (2)'!$A$21:$L$335,12,FALSE) -> 2546599.2 | N30: =D30-L30 -> 388006 | P30: =IF(D30=0,0,N30/D30) -> 0.13221745 | S30: =VLOOKUP(A30,'Level 3'!$A$21:$L$320,12,FALSE) -> 2270799.5 | T30: =L30-S30 -> 275799.7 | U30: =IF(L30=0,0,T30/L30) -> 0.10830118
A31: Elevator Shaft | C31: ='Level 1'!K45 -> 152000 | F31: =VLOOKUP(A31,'Level 1.1 UPDATE A'!$A$21:$K$292,11,FALSE) -> 114000 | H31: =C31-F31 -> 38000 | I31: =IF(D31=0,0,H31/D31) -> 0 | K31: =VLOOKUP(A31,'Level 2 - Transmitted (2)'!$A$20:$K$335,11,FALSE) -> 129600 | N31: =C31-K31 -> 22400 | P31: =IF(D31=0,0,N31/D31) -> 0 | R31: =VLOOKUP(A31,'Level 3'!$A$20:$K$319,11,FALSE) -> 168000 | T31: =K31-R31 -> -38400 | U31: =IF(K31=0,0,T31/K31) -> -0.2962963
A32: Trash Enclosure | C32: ='Level 1'!K46 -> 79800 | F32: =VLOOKUP(A32,'Level 1.1 UPDATE A'!$A$21:$K$292,11,FALSE) -> 79800 | H32: =C32-F32 -> 0 | I32: =IF(D32=0,0,H32/D32) -> 0 | K32: =VLOOKUP(A32,'Level 2 - Transmitted (2)'!$A$20:$K$335,11,FALSE) -> 91000 | N32: =C32-K32 -> -11200 | P32: =IF(D32=0,0,N32/D32) -> 0 | R32: =VLOOKUP(A32,'Level 3'!$A$20:$K$319,11,FALSE) -> 91000 | T32: =K32-R32 -> 0 | U32: =IF(K32=0,0,T32/K32) -> 0
A33: Masonry Veneer | C33: ='Level 1'!K47 -> 0 | F33: =VLOOKUP(A33,'Level 1.1 UPDATE A'!$A$21:$K$292,11,FALSE) -> 0 | H33: =C33-F33 -> 0 | I33: =IF(D33=0,0,H33/D33) -> 0 | K33: =VLOOKUP(A33,'Level 2 - Transmitted (2)'!$A$20:$K$335,11,FALSE) -> 0 | N33: =C33-K33 -> 0 | P33: =IF(D33=0,0,N33/D33) -> 0 | R33: =VLOOKUP(A33,'Level 3'!$A$20:$K$319,11,FALSE) -> 0 | T33: =K33-R33 -> 0 | U33: =IF(K33=0,0,T33/K33) -> 0
A34: Masonry Veneer Pool Area | C34: ='Level 1'!K48 -> 6000 | F34: =VLOOKUP(A34,'Level 1.1 UPDATE A'!$A$21:$K$292,11,FALSE) -> 6000 | H34: =C34-F34 -> 0 | I34: =IF(D34=0,0,H34/D34) -> 0 | K34: =VLOOKUP(A34,'Level 2 - Transmitted (2)'!$A$20:$K$335,11,FALSE) -> 40000 | N34: =C34-K34 -> -34000 | P34: =IF(D34=0,0,N34/D34) -> 0 | R34: =VLOOKUP(A34,'Level 3'!$A$20:$K$319,11,FALSE) -> 40000 | T34: =K34-R34 -> 0 | U34: =IF(K34=0,0,T34/K34) -> 0
A35: Pool Eq. Shower Stone | C35: ='Level 1'!K49 -> 9000 | F35: =VLOOKUP(A35,'Level 1.1 UPDATE A'!$A$21:$K$292,11,FALSE) -> 9000 | H35: =C35-F35 -> 0 | I35: =IF(D35=0,0,H35/D35) -> 0 | K35: =VLOOKUP(A35,'Level 2 - Transmitted (2)'!$A$20:$K$335,11,FALSE) -> 15000 | N35: =C35-K35 -> -6000 | P35: =IF(D35=0,0,N35/D35) -> 0 | R35: =VLOOKUP(A35,'Level 3'!$A$20:$K$319,11,FALSE) -> 15000 | T35: =K35-R35 -> 0 | U35: =IF(K35=0,0,T35/K35) -> 0
A36: Masonry | D36: ='Level 1'!L44 -> 246800 | G36: =VLOOKUP(A36,'Level 1.1 UPDATE A'!$A$20:$L$330,12,FALSE) -> 208800 | H36: =D36-G36 -> 38000 | I36: =IF(D36=0,0,H36/D36) -> 0.15397083 | L36: =VLOOKUP(A36,'Level 2 - Transmitted (2)'!$A$21:$L$335,12,FALSE) -> 275600 | N36: =D36-L36 -> -28800 | P36: =IF(D36=0,0,N36/D36) -> -0.11669368 | S36: =VLOOKUP(A36,'Level 3'!$A$21:$L$320,12,FALSE) -> 314000 | T36: =L36-S36 -> -38400 | U36: =IF(L36=0,0,T36/L36) -> -0.13933237
A37: Structural Steel | C37: ='Level 1'!K51 -> 125000 | F37: =VLOOKUP(A37,'Level 1.1 UPDATE A'!$A$21:$K$292,11,FALSE) -> 125000 | H37: =C37-F37 -> 0 | I37: =IF(D37=0,0,H37/D37) -> 0 | K37: =VLOOKUP(A37,'Level 2 - Transmitted (2)'!$A$20:$K$335,11,FALSE) -> 240254.58 | N37: =C37-K37 -> -115254.58 | P37: =IF(D37=0,0,N37/D37) -> 0 | R37: =VLOOKUP(A37,'Level 3'!$A$20:$K$319,11,FALSE) -> 298082.6 | T37: =K37-R37 -> -57828.024 | U37: =IF(K37=0,0,T37/K37) -> -0.24069479
A38: Elevator Shaft Iron | C38: ='Level 1'!K52 -> 24240 | F38: =VLOOKUP(A38,'Level 1.1 UPDATE A'!$A$21:$K$292,11,FALSE) -> 16160 | H38: =C38-F38 -> 8080 | I38: =IF(D38=0,0,H38/D38) -> 0 | K38: =VLOOKUP(A38,'Level 2 - Transmitted (2)'!$A$20:$K$335,11,FALSE) -> 16400 | N38: =C38-K38 -> 7840 | P38: =IF(D38=0,0,N38/D38) -> 0 | R38: =VLOOKUP(A38,'Level 3'!$A$20:$K$319,11,FALSE) -> 16400 | T38: =K38-R38 -> 0 | U38: =IF(K38=0,0,T38/K38) -> 0
A39: Stair Handrails | C39: ='Level 1'!K53 -> 120000 | F39: =VLOOKUP(A39,'Level 1.1 UPDATE A'!$A$21:$K$292,11,FALSE) -> 88000 | H39: =C39-F39 -> 32000 | I39: =IF(D39=0,0,H39/D39) -> 0 | K39: =VLOOKUP(A39,'Level 2 - Transmitted (2)'!$A$20:$K$335,11,FALSE) -> 67500 | N39: =C39-K39 -> 52500 | P39: =IF(D39=0,0,N39/D39) -> 0 | R39: =VLOOKUP(A39,'Level 3'!$A$20:$K$319,11,FALSE) -> 94000 | T39: =K39-R39 -> -26500 | U39: =IF(K39=0,0,T39/K39) -> -0.39259259
A40: Garage Stair Railings | C40: ='Level 1'!K54 -> 0 | F40: =VLOOKUP(A40,'Level 1.1 UPDATE A'!$A$21:$K$292,11,FALSE) -> 0 | H40: =C40-F40 -> 0 | I40: =IF(D40=0,0,H40/D40) -> 0 | K40: =VLOOKUP(A40,'Level 2 - Transmitted (2)'!$A$20:$K$335,11,FALSE) -> 0 | N40: =C40-K40 -> 0 | P40: =IF(D40=0,0,N40/D40) -> 0 | R40: =VLOOKUP(A40,'Level 3'!$A$20:$K$319,11,FALSE) -> 0 | T40: =K40-R40 -> 0 | U40: =IF(K40=0,0,T40/K40) -> 0
A41: Shower Cover | K41: 0 | N41: =C41-K41 -> 0 | P41: =IF(D41=0,0,N41/D41) -> 0 | R41: =VLOOKUP(A41,'Level 3'!$A$20:$K$319,11,FALSE) -> 6000 | T41: =K41-R41 -> -6000 | U41: =IF(K41=0,0,T41/K41) -> 0
A42: Cabana Iron | C42: ='Level 1'!K55 -> 0 | F42: =VLOOKUP(A42,'Level 1.1 UPDATE A'!$A$21:$K$292,11,FALSE) -> 0 | H42: =C42-F42 -> 0 | I42: =IF(D42=0,0,H42/D42) -> 0 | K42: =VLOOKUP(A42,'Level 2 - Transmitted (2)'!$A$20:$K$335,11,FALSE) -> 0 | N42: =C42-K42 -> 0 | P42: =IF(D42=0,0,N42/D42) -> 0 | R42: =VLOOKUP(A42,'Level 3'!$A$20:$K$319,11,FALSE) -> 0 | T42: =K42-R42 -> 0 | U42: =IF(K42=0,0,T42/K42) -> 0
A43: Pool Equipment Gate | C43: ='Level 1'!K56 -> 1950 | F43: =VLOOKUP(A43,'Level 1.1 UPDATE A'!$A$21:$K$292,11,FALSE) -> 1950 | H43: =C43-F43 -> 0 | I43: =IF(D43=0,0,H43/D43) -> 0 | K43: =VLOOKUP(A43,'Level 2 - Transmitted (2)'!$A$20:$K$335,11,FALSE) -> 2000 | N43: =C43-K43 -> -50 | P43: =IF(D43=0,0,N43/D43) -> 0 | R43: =VLOOKUP(A43,'Level 3'!$A$20:$K$319,11,FALSE) -> 2000 | T43: =K43-R43 -> 0 | U43: =IF(K43=0,0,T43/K43) -> 0
A44: Iron Railings | C44: ='Level 1'!K57 -> 250976 | F44: =VLOOKUP(A44,'Level 1.1 UPDATE A'!$A$21:$K$292,11,FALSE) -> 269744 | H44: =C44-F44 -> -18768 | I44: =IF(D44=0,0,H44/D44) -> 0 | K44: =VLOOKUP(A44,'Level 2 - Transmitted (2)'!$A$20:$K$335,11,FALSE) -> 282872.4 | N44: =C44-K44 -> -31896.4 | P44: =IF(D44=0,0,N44/D44) -> 0 | R44: =VLOOKUP(A44,'Level 3'!$A$20:$K$319,11,FALSE) -> 300204 | T44: =K44-R44 -> -17331.6 | U44: =IF(K44=0,0,T44/K44) -> -0.061270028
...

Sheet Level 2 - Transmitted (2)
A1: Project Details | D1: Unit Breakdown | H1: Breakdown Per Building | P1: List of Take offs | S1: List of Take offs | V1: List of Take offs
A2: Project | B2: West Henderson | D2: Unit Type | E2: Number | F2: % | H2: Bldg. | I2: Levels | J2: Unit | K2: 1 Br - 1 Ba | L2: 2 Br - 1 Ba | M2: 2 Br - 2 Ba | N2: 3 Br - 2 Ba | O2: GSF | P2: Slab SF | Q2: 145399.85 | R2: GSF (Provided in Matrix) | S2: 1 Br - 1 Ba Counter | T2: 9150.98 | U2: SF | V2: Structural | W2: 59616.52 | AP2: Finish Carpentry | AW2: Exhaust Per Building | BE2: Unit Breakdown | BF2: Wire Shelving LF | BG2: Bedrooms | BH2: Bathrooms | BI2: Unit Count | BJ2: Windows
A3: Budget Level | B3: Level 2 | D3: Studios | E3: 0 | F3: 0 | H3: 1 | I3: 3 | J3: 169 | K3: 87 | L3: 17 | M3: 48 | N3: 17 | O3: 185300 | P3: Elevators | Q3: 4 | R3: Count | S3: 2 Br - 1 Ba Counter | T3: 2673.44 | U3: SF | AA3: Railing Estimate | AE3: Building 3 | AF3: =21*7 -> 147 | AH3: Stucco | AJ3: 1.1 | AP3: Unit Type | AQ3: Number | AR3: TP $ | AS3: % | AT3: % | AW3: Building | AX3: Floors | AY3: U / Floor | AZ3: Total Units | BA3: Cost / U | BB3: Total | BE3: A1A | BF3: 41 | BG3: 1 | BH3: 1 | BI3: 9 | BJ3: 3 | BK3: =BJ3*BI3 -> 27
A4: Product | B4: Affordable | D4: 1 Br - 1 Ba | E4: 178 | F4: 0.45641026 | H4: 2 | I4: 2 | J4: 24 | K4: 9 | L4: 7 | M4: 8 | N4: 0 | O4: 24353 | P4: Elevators Stops | Q4: 12 | R4: Count | S4: 2 Br - 2 Ba Counter | T4: 2893.8 | U4: SF | AA4: Building 1 | AF4: =14*7 -> 98 | AH4: Building 1 | AI4: =88591.52+6310.7+12391.66+5996.96 -> 113290.84 | AJ4: =AI4*$AJ$3 -> 124619.92 | AP4: Studios | AQ4: 0 | AR4: 3192.5 | AS4: 0 | AT4: =AR4*(1+AS4) -> 3192.5 | AW4: Building 1 | AX4: 3 | AY4: 9 | AZ4: =AY4*AX4 -> 27 | BA4: =275 -> 275 | BB4: =BA4*AZ4 -> 7425 | BE4: B1A | BF4: 31 | BG4: 1 | BH4: 1 | BI4: 106 | BJ4: 3 | BK4: =BJ4*BI4 -> 318
A5: UPDATED | B5: 45884 | D5: 2 Br - 1 Ba | E5: 49 | F5: 0.12564103 | H5: 3 | I5: 3 | J5: 173 | K5: 73 | L5: 18 | M5: 51 | N5: 31 | O5: 192543 | P5: Trash Encl. | Q5: 13 | R5: Provided in Site Plan | S5: 3 Br - 2 Ba Counter | T5: 3543.36 | U5: SF | AA5: Northwest | AB5: =21*4+8*8+7*6 -> 190 | AF5: =8*22 -> 176 | AH5: Building 2 | AI5: =31183.77/2 -> 15591.885 | AJ5: =AI5*$AJ$3 -> 17151.074 | AP5: 1 Br - 1 Ba | AQ5: 171 | AR5: 3192.5 | AS5: 0 | AT5: =AR5*(1+AS5) -> 3192.5 | AW5: Building 2 | AX5: 2 | AY5: 2 | AZ5: =AY5*AX5 -> 4 | BA5: =275 -> 275 | BB5: =BA5*AZ5 -> 1100 | BE5: B1AE | BF5: 31 | BG5: 1 | BH5: 1 | BI5: 3 | BJ5: 3 | BK5: =BJ5*BI5 -> 9
A6: Timeline | B6: 26 | D6: 2 Br - 2 Ba | E6: 115 | F6: 0.29487179 | H6: 4 | I6: 2 | J6: 24 | K6: 9 | L6: 7 | M6: 8 | N6: 0 | O6: 24353 | P6: Stairs | Q6: 17 | R6: Count | S6: 1x1 Decks | T6: 3440 | U6: SF | AA6: Southwest | AB6: =14*4+21*2+8*6 -> 146 | AF6: =7*10 -> 70 | AH6: Building 3 | AI6: =65053.99+12730.03+12624.72 -> 90408.74 | AJ6: =AI6*$AJ$3 -> 99449.614 | AP6: 2 Br - 1 Ba | AQ6: 52 | AR6: 3192.5 | AS6: 0 | AT6: =AR6*(1+AS6) -> 3192.5 | AW6: Building 3 | AX6: 2 | AY6: 9 | AZ6: =AY6*AX6 -> 18 | BA6: =275 -> 275 | BB6: =BA6*AZ6 -> 4950 | BE6: B1B | BF6: 19 | BG6: 1 | BH6: 1 | BI6: 60 | BJ6: 2 | BK6: =BJ6*BI6 -> 120
A7: Floors | B7: 2 & 3 Levels | D7: 3 Br - 2 Ba | E7: 48 | F7: 0.12307692 | P7: Pool | Q7: 1 | S7: 2x1 Decks | U7: SF | AA7: Northeast | AB7: =21*2+14*2+8*6 -> 118 | AF7: =SUM(AF3:AF6) -> 491 | AH7: Building 4 | AI7: =31183.77/2 -> 15591.885 | AJ7: =AI7*$AJ$3 -> 17151.074 | AP7: 2 Br - 2 Ba | AQ7: 118 | AR7: 3192.5 | AS7: 0.1 | AT7: =AR7*(1+AS7) -> 3511.75 | AW7: Building 4 | AX7: 3 | AY7: 3 | AZ7: =AY7*AX7 -> 9 | BA7: =275 -> 275 | BB7: =BA7*AZ7 -> 2475 | BE7: A2B | BF7: 66 | BG7: 2 | BH7: 2 | BI7: 8 | BJ7: 3 | BK7: =BJ7*BI7 -> 24
A8: Bldg. SF | B8: 422635 | D8: Totals | E8: 390 | F8: 1 | H8: Totals | I8: 10 | J8: 390 | K8: 178 | L8: 49 | M8: 115 | N8: 48 | O8: 426549 | P8: Gym | Q8: 2 | S8: Lightweight | T8: 261305.65 | U8: SF | AA8: Southeast | AB8: =21*2+14*8+8*12+7*8 -> 306 | AJ8: =SUM(AJ4:AJ7) -> 258371.69 | AK8: sf | AP8: 3 Br - 2 Ba | AQ8: 49 | AR8: 3192.5 | AS8: 0.2 | AT8: =AR8*(1+AS8) -> 3831 | AW8: Building 5 | AX8: 2 | AY8: 2 | AZ8: =AY8*AX8 -> 4 | BA8: 275 | BB8: =BA8*AZ8 -> 1100 | BE8: B2A | BF8: 45 | BG8: 2 | BH8: 1 | BI8: 6 | BJ8: 3 | BK8: =BJ8*BI8 -> 18
A9: Acres | B9: 15.826 | D9: Parking | P9: Iron Rail | Q9: 3074.7 | R9: LF | S9: Pavers | T9: 900 | U9: SF | AA9: More | AB9: =21*4+8*6 -> 132 | AC9: =SUM(AB5:AB9) -> 892 | AJ9: =AJ8/9 -> 28707.965 | AK9: sy | AP9: Totals | AQ9: =SUM(AQ4:AQ8) -> 390 | AT9: =SUMPRODUCT(AQ4:AQ8,AT4:AT8)/AQ9 -> 3369.3154 | BB9: =SUM(BB4:BB8) -> 17050 | BE9: B2B | BF9: 68 | BG9: 2 | BH9: 2 | BI9: 107 | BJ9: 3 | BK9: =BJ9*BI9 -> 321
A10: Site SF | B10: 689380.56 | D10: Garage Parking | F10: 0 | P10: Roofing | Q10: 1734.0111 | R10: Square | S10: Pool Deck | T10: 7964 | U10: SF | AT10: =AT9-AR8 -> 176.81538 | BE10: B2C | BF10: 44 | BG10: 2 | BH10: 1 | BI10: 43 | BJ10: 6 | BK10: =BJ10*BI10 -> 258
A11: Buildings | B11: 4 | D11: Cover Parking | F11: 375 | P11: Stucco | Q11: 28186.002 | R11: Square Yard | S11: Pool Fence | T11: 372 | U11: LF | V11: Corridor Bldg. 1 | W11: 19288 | X11: SF | AA11: Building 2 & 5 | AE11: Building 4 | AF11: =14*8 -> 112 | AT11: =AT10/AR8 -> 0.055384615 | BE11: A3A | BF11: 48 | BG11: 3 | BH11: 2 | BI11: 3 | BJ11: 4 | BK11: =BJ11*BI11 -> 12
A12: Reports Available | D12: Open Parking | F12: 320 | P12: Liav GSF | Q12: 329873 | R12: SF | S12: Dog Park Fence | T12: 400 | U12: LF | V12: Corridor Bldg. 2 | W12: 2159 | X12: SF | AA12: Northwest | AF12: =20*8 -> 160 | BE12: B3A | BF12: 55 | BG12: 3 | BH12: 2 | BI12: 45 | BJ12: 4 | BK12: =BJ12*BI12 -> 180
A13: Site Evaluation Report (GCW) | B13: 45062 | D13: Accessible Parking | F13: 16 | P13: Carports | Q13: 375 | R13: Count | S13: Common Bldg. 1 | T13: 7476 | U13: SF | V13: Corridor Bldg. 3 | W13: 20355 | X13: SF | AA13: Southwest | AF13: =8*18 -> 144 | BF13: =SUMPRODUCT(BF3:BF12,BI3:BI12) -> 17473 | BI13: =SUM(BI3:BI12) -> 390 | BK13: =SUM(BK3:BK12) -> 1287
A14: Soils Report (Universal) | B14: 45848 | D14: Private Garages | F14: 0 | J14: TOTAL COST | L14: 79847909 | P14: Stairs Landings | Q14: 47 | R14: Landings | S14: Common Bldg. 2 | T14: 0 | U14: SF | V14: Corridor Bldg. 4 | W14: 2159 | X14: SF | AA14: Northeast | AF14: =7*12 -> 84 | BK14: =(6+7)*2+4 -> 30
A15: Alta Survey (Wallace) | B15: 45583 | D15: Total Parking Provided | F15: 711 | J15: PER UNIT | L15: 204738.23 | P15: Pump House | Q15: 1 | R15: EA | S15: Common Bldg. 3 | T15: 1888 | U15: SF | V15: TOTAL | W15: 43961 | X15: SF | AA15: Southeast | AB15: =21*2+14*2+8*6+7*6 -> 160 | AC15: =AB15*2 -> 320 | AF15: =SUM(AF11:AF14) -> 500 | BK15: 7 | BL15: 10
A16: Plans | B16: 45825 | D16: Parking Ratio | F16: 1.8230769 | J16: PER GSF | L16: 188.92877 | P16: Lock Boxes | Q16: 10 | R16: EA | S16: Common Bldg. 4 | T16: 1557 | U16: SF | V16: BBQ | W16: 8 | X16: Count | BK16: 13 | BL16: 6
A17: NVE Planning Memo | B17: 45043 | P17: Awning Small | Q17: 58 | R17: EA | S17: Common Bldg. 5 | T17: 0 | U17: SF | V17: Fire Pumps | W17: 1 | X17: Count | AA17: B1B Railings | AB17: =12.5*62 -> 775 | BK17: 22 | BL17: 3
P18: Awning Large | Q18: 10 | R18: EA | S18: HVAC ADD Count | T18: 135.25641 | V18: Asphalt | W18: 256408.47 | BL18: =BK13+BK14+BK15+BK16+BK17+BL15+BL16+BL17 -> 1378
A19: Description | B19: Cost Code | C19: Cost Category | D19: Sub job | E19: Source | F19: Unit Meas. | G19: QTY | H19: Unit Cost | I19: Escalation % | J19: T. Unit Cost | K19: Sub Total | L19: Total | M19: Description / Details | BL19: =BL18*368 -> 507104
A20: General Requirements | B20: 01 | L20: 3849810.3
A21: General Requirements | B21: 01 | C21: S | F21: Mo | G21: 26 | H21: 148069.63 | I21: 0 | J21: 148069.63 | K21: 3849810.3 | AX21: Slab | AY21: Lightweight | AZ21: Roofing
A22: Existing Conditions | B22: 02 | L22: 12000 | AW22: Building 1 | AX22: 59487.01 | AY22: =58247.42+58464.84 -> 116712.26 | AZ22: =62310.84+10234.24 -> 72545.08 | BE22: 15 | BG22: 2
A23: Potholing | B23: 02-3213 | C23: S | D23: ON-SITE | E23: Allowance | G23: 1 | H23: 12000 | I23: 0 | J23: 12000 | K23: 12000 | AW23: Building 2 | AX23: 11996.7 | AY23: 11552.49 | AZ23: =12091.16+2030.7 -> 14121.86 | BE23: 5 | BG23: 2
A24: Concrete | B24: 03 | L24: 2546599.2 | AW24: Building 3 | AX24: 61844.96 | AY24: =60632.4+60507.06 -> 121139.46 | AZ24: =62164.89+10362.59 -> 72527.48 | BE24: 8 | BG24: 3
A25: Slabs | B25: 03-3101 | C25: S | D25: BUILDING | E25: Torrey Pines | F25: SF | G25: 145399.85 | H25: 11.5 | I25: 0 | J25: 11.5 | K25: 1672098.3 | M25: Proposal from NRC at $9.16. Conversation with NRC said he would at $11 to 11.50 if he wasn't aggressive. | AW25: Building 4 | AX25: 12071.18 | AY25: 11901.44 | AZ25: =12174.39+2032.3 -> 14206.69 | BE25: 22 | BG25: 1
A26: Deepened Footings | B26: 03-3101 | C26: S | D26: BUILDING | E26: N/A | J26: 0 | K26: 0 | AW26: Total | AX26: =SUM(AX22:AX25) -> 145399.85 | AY26: =SUM(AY22:AY25) -> 261305.65 | AZ26: =SUM(AZ22:AZ25) -> 173401.11 | BE26: 8 | BG26: 1
